Workbook

Sheet Instructions
A1: TIB SYSTEMS LLC | SAP Controls Project Foundation Workbook Set
A2: W11 — Test Workpapers
A4: Purpose
A5: A workpaper records what the tester actually did, so a reviewer who was not involved can understand, reperform and reach the same conclusion. This file holds the standard workpaper structure, the list of 15 templates by control area, and a register of workpapers.
A7: How to use this workbook
A8: 1. Paste TEST-IDs from W10 into Ref_TEST.
A9: 2. For each test, copy the Workpaper tab (right-click > Move or Copy) and rename it with the TEST-ID.
A10: 3. Complete header, population/IPE, sample, procedure and attribute grid. Every Met or Exception needs an EV-ID reference.
A11: 4. Describe exceptions and root cause. The suggested result is a formula; the reviewer sets the final result.
A12: 5. Log each workpaper in WP_Register. Raise DEF-IDs in W13.
A14: Colour legend
A15: Yellow cells with blue text = you enter data here. Grey cells = formulas (do not overwrite). Row 5 of each register is a worked ABC Manufacturing example: overwrite it with your first record.
... A26: Column dictionary
A27: Tab | B27: Field | C27: Definition | D27: Allowed values / rule | E27: Type
A28: WP_Register | B28: WP ref | C28: Workpaper reference | D28: e.g. WP-PC-01_<TEST-ID> | E28: Input
A29: WP_Register | B29: TEST-ID | C29: Test the workpaper supports | D29: Must exist in W10 (Ref_TEST) | E29: Input
A30: WP_Register | B30: Template | C30: Standard template used | D30: From Templates tab | E30: Input
A31: WP_Register | B31: Tester | C31: Who performed | D31: Name | E31: Input
A32: WP_Register | B32: Items tested | C32: From the Workpaper tab | D32: Number | E32: Input
A33: WP_Register | B33: Items with exception | C33: From the Workpaper tab | D33: Number | E33: Input
A34: WP_Register | B34: Result | C34: Outcome (after review) | D34: Dropdown | E34: Input
A35: WP_Register | B35: Reviewed by | C35: Reviewer | D35: Name; different from tester | E35: Input
A36: WP_Register | B36: Review date | C36: Date | D36: Date | E36: Input
A37: WP_Register | B37: DEF-ID(s) / rationale | C37: Deficiency raised, or false-positive rationale | D37: Required if Exception noted / Ineffective | E37: Input
A38: WP_Register | B38: Status | C38: Progress | D38: Dropdown | E38: Input
A39: WP_Register | B39: Check | C39: Automatic test | D39: Formula | E39: Formula
A41: Version history
A42: 0.1 — October 2026 — initial template (TIB Systems LLC)
A43: Cross-workbook links: keys from other workbooks are pasted as values into the Ref_ tabs, so this file works on its own and never breaks when files are moved.

Sheet WP_Register
A1: W11 — Workpaper Register
A2: One row per workpaper. Row 5 is a worked example.
A4: WP ref | B4: TEST-ID | C4: Template | D4: Tester | E4: Items tested | F4: Items with exception | G4: Result | H4: Reviewed by | I4: Review date | J4: DEF-ID(s) / rationale | K4: Status | L4: Check
A5: WP-PC-01_C-ITGC-PC-001-TOE | B5: C-ITGC-PC-001-TOE | C5: WP-PC-01 | D5: Tester 1 | E5: 27 | F5: 1 | G5: Exception noted | H5: Manager 1 | I5: 46314 | J5: DEF-011 | K5: Reviewed | L5: =IF(A5="","",IF(COUNTIF(Ref_TEST!$A$2:$A$201,B5)=0,"TEST-ID not in W10",IF(C5="","Template needed",IF(AND(K5="Reviewed",H5=""),"Reviewer needed",IF(AND(F5>0,G5="Effective"),"Exceptions recorded but result Effective",IF(AND(OR(G5="Exception noted",G5="Ineffective"),J5=""),"DEF-ID or rationale needed",IF(AND(H5<>"",H5=D5),"Reviewer must differ from tester","OK"))))))) -> OK
L6: =IF(A6="","",IF(COUNTIF(Ref_TEST!$A$2:$A$201,B6)=0,"TEST-ID not in W10",IF(C6="","Template needed",IF(AND(K6="Reviewed",H6=""),"Reviewer needed",IF(AND(F6>0,G6="Effective"),"Exceptions recorded but result Effective",IF(AND(OR(G6="Exception noted",G6="Ineffective"),J6=""),"DEF-ID or rationale needed",IF(AND(H6<>"",H6=D6),"Reviewer must differ from tester","OK")))))))
L7: =IF(A7="","",IF(COUNTIF(Ref_TEST!$A$2:$A$201,B7)=0,"TEST-ID not in W10",IF(C7="","Template needed",IF(AND(K7="Reviewed",H7=""),"Reviewer needed",IF(AND(F7>0,G7="Effective"),"Exceptions recorded but result Effective",IF(AND(OR(G7="Exception noted",G7="Ineffective"),J7=""),"DEF-ID or rationale needed",IF(AND(H7<>"",H7=D7),"Reviewer must differ from tester","OK")))))))
L8: =IF(A8="","",IF(COUNTIF(Ref_TEST!$A$2:$A$201,B8)=0,"TEST-ID not in W10",IF(C8="","Template needed",IF(AND(K8="Reviewed",H8=""),"Reviewer needed",IF(AND(F8>0,G8="Effective"),"Exceptions recorded but result Effective",IF(AND(OR(G8="Exception noted",G8="Ineffective"),J8=""),"DEF-ID or rationale needed",IF(AND(H8<>"",H8=D8),"Reviewer must differ from tester","OK")))))))
L9: =IF(A9="","",IF(COUNTIF(Ref_TEST!$A$2:$A$201,B9)=0,"TEST-ID not in W10",IF(C9="","Template needed",IF(AND(K9="Reviewed",H9=""),"Reviewer needed",IF(AND(F9>0,G9="Effective"),"Exceptions recorded but result Effective",IF(AND(OR(G9="Exception noted",G9="Ineffective"),J9=""),"DEF-ID or rationale needed",IF(AND(H9<>"",H9=D9),"Reviewer must differ from tester","OK")))))))
L10: =IF(A10="","",IF(COUNTIF(Ref_TEST!$A$2:$A$201,B10)=0,"TEST-ID not in W10",IF(C10="","Template needed",IF(AND(K10="Reviewed",H10=""),"Reviewer needed",IF(AND(F10>0,G10="Effective"),"Exceptions recorded but result Effective",IF(AND(OR(G10="Exception noted",G10="Ineffective"),J10=""),"DEF-ID or rationale needed",IF(AND(H10<>"",H10=D10),"Reviewer must differ from tester","OK")))))))
L11: =IF(A11="","",IF(COUNTIF(Ref_TEST!$A$2:$A$201,B11)=0,"TEST-ID not in W10",IF(C11="","Template needed",IF(AND(K11="Reviewed",H11=""),"Reviewer needed",IF(AND(F11>0,G11="Effective"),"Exceptions recorded but result Effective",IF(AND(OR(G11="Exception noted",G11="Ineffective"),J11=""),"DEF-ID or rationale needed",IF(AND(H11<>"",H11=D11),"Reviewer must differ from tester","OK")))))))
L12: =IF(A12="","",IF(COUNTIF(Ref_TEST!$A$2:$A$201,B12)=0,"TEST-ID not in W10",IF(C12="","Template needed",IF(AND(K12="Reviewed",H12=""),"Reviewer needed",IF(AND(F12>0,G12="Effective"),"Exceptions recorded but result Effective",IF(AND(OR(G12="Exception noted",G12="Ineffective"),J12=""),"DEF-ID or rationale needed",IF(AND(H12<>"",H12=D12),"Reviewer must differ from tester","OK")))))))
L13: =IF(A13="","",IF(COUNTIF(Ref_TEST!$A$2:$A$201,B13)=0,"TEST-ID not in W10",IF(C13="","Template needed",IF(AND(K13="Reviewed",H13=""),"Reviewer needed",IF(AND(F13>0,G13="Effective"),"Exceptions recorded but result Effective",IF(AND(OR(G13="Exception noted",G13="Ineffective"),J13=""),"DEF-ID or rationale needed",IF(AND(H13<>"",H13=D13),"Reviewer must differ from tester","OK")))))))
L14: =IF(A14="","",IF(COUNTIF(Ref_TEST!$A$2:$A$201,B14)=0,"TEST-ID not in W10",IF(C14="","Template needed",IF(AND(K14="Reviewed",H14=""),"Reviewer needed",IF(AND(F14>0,G14="Effective"),"Exceptions recorded but result Effective",IF(AND(OR(G14="Exception noted",G14="Ineffective"),J14=""),"DEF-ID or rationale needed",IF(AND(H14<>"",H14=D14),"Reviewer must differ from tester","OK")))))))
L15: =IF(A15="","",IF(COUNTIF(Ref_TEST!$A$2:$A$201,B15)=0,"TEST-ID not in W10",IF(C15="","Template needed",IF(AND(K15="Reviewed",H15=""),"Reviewer needed",IF(AND(F15>0,G15="Effective"),"Exceptions recorded but result Effective",IF(AND(OR(G15="Exception noted",G15="Ineffective"),J15=""),"DEF-ID or rationale needed",IF(AND(H15<>"",H15=D15),"Reviewer must differ from tester","OK")))))))
L16: =IF(A16="","",IF(COUNTIF(Ref_TEST!$A$2:$A$201,B16)=0,"TEST-ID not in W10",IF(C16="","Template needed",IF(AND(K16="Reviewed",H16=""),"Reviewer needed",IF(AND(F16>0,G16="Effective"),"Exceptions recorded but result Effective",IF(AND(OR(G16="Exception noted",G16="Ineffective"),J16=""),"DEF-ID or rationale needed",IF(AND(H16<>"",H16=D16),"Reviewer must differ from tester","OK")))))))
L17: =IF(A17="","",IF(COUNTIF(Ref_TEST!$A$2:$A$201,B17)=0,"TEST-ID not in W10",IF(C17="","Template needed",IF(AND(K17="Reviewed",H17=""),"Reviewer needed",IF(AND(F17>0,G17="Effective"),"Exceptions recorded but result Effective",IF(AND(OR(G17="Exception noted",G17="Ineffective"),J17=""),"DEF-ID or rationale needed",IF(AND(H17<>"",H17=D17),"Reviewer must differ from tester","OK")))))))
... L204: =IF(A204="","",IF(COUNTIF(Ref_TEST!$A$2:$A$201,B204)=0,"TEST-ID not in W10",IF(C204="","Template needed",IF(AND(K204="Reviewed",H204=""),"Reviewer needed",IF(AND(F204>0,G204="Effective"),"Exceptions recorded but result Effective",IF(AND(OR(G204="Exception noted",G204="Ineffective"),J204=""),"DEF-ID or rationale needed",IF(AND(H204<>"",H204=D204),"Reviewer must differ from tester","OK")))))))

Sheet Workpaper
A1: Workpaper — standard structure (copy this tab for each test)
A2: Yellow = input. Grey = formula. Rows 34–36 and header values are ABC examples (transport test): overwrite them.
A3: TEST-ID | B3: C-ITGC-PC-001-TOE
A4: CTRL-ID | B4: C-ITGC-PC-001
A5: RISK-ID(s) | B5: R-TECH-003
A6: Control description | B6: Basis (who) imports each transport to PRD only after an approved change ticket and QAS test sign-off (what), on every import (when), using STMS and the ITSM ticket (how); evidence is the ticket and TPALOG record (evidence).
A7: System (SYS-ID) | B7: SYS-03
A8: Test type | B8: TOE
A9: Test period | B9: 01-Jan-2026 to 30-Sep-2026
A10: Tester / date | B10: Tester 1 / 16-Oct-2026
A11: Reviewer / date
A12: Objective | B12: Did every transport imported to PRD in the period have approved change, testing and independent import?
A14: Population & IPE
A15: Population EV-ID | B15: EV-019
A16: Record count | B16: 312
A17: IPE-ID / result | B17: IPE-002 / Pass
A19: Sample
A20: SMP-ID | B20: SMP-003
A21: Selection method / seed | B21: Random, seed 4471; plus 2 targeted ITAC-table transports
A23: Procedure performed (numbered steps actually done, with t-codes and tables)
A24: Step 1 | B24: Confirm IPE-002 = Pass. Match every transport in TPALOG to a ticket reference (population analysis).
A25: Step 2 | B25: Select 25 transports by seeded random selection plus targeted items; log in W12.
A26: Step 3 | B26: Request tickets and test evidence (PBC-040).
A27: Step 4 | B27: For each item test attributes A–E.
A28: Step 5
A29: Step 6
A31: Attribute grid (Met / Exception / n/a for each sample item)
A32: # | B32: Sample item | C32: A | D32: B | E32: C | F32: D | G32: E | H32: F | I32: EV-ID ref | J32: Notes | K32: Item result
B33: Attribute description → | C33: Ticket approved before import | D33: QAS test + sign-off | E33: Imported by non-developer | F33: Content agrees to ticket | G33: Emergency approved ≤2 days
A34: =IF(B34="","",ROW()-33) -> 1 | B34: ECDK900114 | C34: Met | D34: Met | E34: Met | F34: Met | G34: n/a | I34: EV-052 | J34: Program fix | K34: =IF(B34="","",IF(COUNTIF(C34:H34,"Exception")>0,"Exception",IF(COUNTA(C34:H34)=0,"Not tested","Met"))) -> Met
A35: =IF(B35="","",ROW()-33) -> 2 | B35: ECDK900187 | C35: Met | D35: Exception | E35: Met | F35: Met | G35: n/a | I35: EV-053 | J35: No QAS sign-off attached | K35: =IF(B35="","",IF(COUNTIF(C35:H35,"Exception")>0,"Exception",IF(COUNTA(C35:H35)=0,"Not tested","Met"))) -> Exception
A36: =IF(B36="","",ROW()-33) -> 3 | B36: ECDK900201 | C36: Met | D36: Met | E36: Met | F36: Met | G36: n/a | I36: EV-054 | J36: Targeted: T169G change | K36: =IF(B36="","",IF(COUNTIF(C36:H36,"Exception")>0,"Exception",IF(COUNTA(C36:H36)=0,"Not tested","Met"))) -> Met
A37: =IF(B37="","",ROW()-33) | K37: =IF(B37="","",IF(COUNTIF(C37:H37,"Exception")>0,"Exception",IF(COUNTA(C37:H37)=0,"Not tested","Met")))
A38: =IF(B38="","",ROW()-33) | K38: =IF(B38="","",IF(COUNTIF(C38:H38,"Exception")>0,"Exception",IF(COUNTA(C38:H38)=0,"Not tested","Met")))
A39: =IF(B39="","",ROW()-33) | K39: =IF(B39="","",IF(COUNTIF(C39:H39,"Exception")>0,"Exception",IF(COUNTA(C39:H39)=0,"Not tested","Met")))
A40: =IF(B40="","",ROW()-33) | K40: =IF(B40="","",IF(COUNTIF(C40:H40,"Exception")>0,"Exception",IF(COUNTA(C40:H40)=0,"Not tested","Met")))
A41: =IF(B41="","",ROW()-33) | K41: =IF(B41="","",IF(COUNTIF(C41:H41,"Exception")>0,"Exception",IF(COUNTA(C41:H41)=0,"Not tested","Met")))
A42: =IF(B42="","",ROW()-33) | K42: =IF(B42="","",IF(COUNTIF(C42:H42,"Exception")>0,"Exception",IF(COUNTA(C42:H42)=0,"Not tested","Met")))
A43: =IF(B43="","",ROW()-33) | K43: =IF(B43="","",IF(COUNTIF(C43:H43,"Exception")>0,"Exception",IF(COUNTA(C43:H43)=0,"Not tested","Met")))
A44: =IF(B44="","",ROW()-33) | K44: =IF(B44="","",IF(COUNTIF(C44:H44,"Exception")>0,"Exception",IF(COUNTA(C44:H44)=0,"Not tested","Met")))
...

Sheet Templates
A1: Workpaper templates by control area
A2: Choose the template for each test. SAP navigation and worked tests are in Part 3A and 3B of the manual.
A4: Template | B4: Control area | C4: Typical SAP sources
A5: WP-AC-01 | B5: User provisioning | C5: GRC ARM requests, SU01 change documents, USR02
A6: WP-AC-02 | B6: Termination (leavers) | C6: HR leavers report, USR02 lock/validity, last logon
A7: WP-AC-03 | B7: User access review | C7: GRC UAR campaign, review sign-offs, removal evidence
A8: WP-AC-04 | B8: Privileged and generic IDs | C8: SUIM by profile, USR02 user types, DDIC/SAP* status
A9: WP-AC-05 | B9: Emergency access (Firefighter) | C9: GRC EAM logs, request/approval, controller review
A10: WP-AC-06 | B10: SoD and sensitive access | C10: GRC ARA results, W06 ruleset, mitigation assignment
A11: WP-AC-07 | B11: Password and logon parameters | C11: RZ11 / RSPARAM
A12: WP-PC-01 | B12: Transport management | C12: STMS import history, E070/E071, ITSM tickets
A13: WP-PC-02 | B13: System and client change settings | C13: SCC4, SE06, change logs
A14: WP-PC-03 | B14: Direct changes / debug in production | C14: Security audit log, S_DEVELOP holders
A15: WP-CO-01 | B15: Batch job monitoring | C15: SM37, TBTCO/TBTCP, failure tickets
... A19: WP-IPE-01 | B19: Key reports | C19: Report logic, parameters, completeness and accuracy procedures

Sheet Ref_TEST
A1: TEST-IDs (paste from W10 Test_Plan)
A2: C-ITGC-PC-001-TOD
A3: C-ITGC-PC-001-TOE
A4: C-ITGC-AC-002-TOE
A5: C-ITAC-004-TOE

Sheet Lists
A1: TRes | B1: TStat
A2: Not started | B2: Not started
A3: Effective | B3: In progress
A4: Exception noted | B4: Ready for review
A5: Ineffective | B5: Reviewed
B6: Closed

Sheet Checks
A1: W11 — Completion checks
A2: All checks are formulas. A workbook passes its gate when every status reads PASS (INFO rows are counts for your information).
A3: Overall | B3: =IF(COUNTIF(C6:C13,"REVIEW")=0,"ALL CHECKS PASS","REVIEW ITEMS: "&COUNTIF(C6:C13,"REVIEW")) -> ALL CHECKS PASS
A5: Check | B5: Count | C5: Status | D5: What to do if REVIEW
A6: Workpapers registered | B6: =COUNTA(WP_Register!A5:A204) -> 1 | C6: INFO | D6: —
A7: Duplicate workpaper refs | B7: =SUMPRODUCT((WP_Register!A5:A204<>"")*(COUNTIF(WP_Register!A5:A204,WP_Register!A5:A204)>1)) -> 0 | C7: =IF(B7=0,"PASS","REVIEW") -> PASS | D7: One register row per workpaper.
A8: Register rows needing attention | B8: =SUMPRODUCT((WP_Register!L5:L204<>"")*(WP_Register!L5:L204<>"OK")*(LEFT(WP_Register!L5:L204,2)<>"OK")) -> 0 | C8: =IF(B8=0,"PASS","REVIEW") -> PASS | D8: Read the Check column.
A9: W10 tests with no workpaper | B9: =SUMPRODUCT((Ref_TEST!A2:A201<>"")*(COUNTIF(WP_Register!B5:B204,Ref_TEST!A2:A201)=0)) -> 3 | C9: INFO | D9: Create a workpaper from the Workpaper tab for each test.
A10: Workpapers reviewed | B10: =COUNTIF(WP_Register!K5:K204,"Reviewed") -> 1 | C10: INFO | D10: Reviewer signs off before the result is entered in W10.
A11: Exceptions with no DEF-ID or rationale | B11: =SUMPRODUCT(((WP_Register!G5:G204="Exception noted")+(WP_Register!G5:G204="Ineffective"))*(WP_Register!J5:J204="")) -> 0 | C11: =IF(B11=0,"PASS","REVIEW") -> PASS | D11: Raise a DEF in W13 or document the false-positive rationale.
A12: Workpaper tab: items tested (current copy) | B12: =Workpaper!B66 -> 3 | C12: INFO | D12: —
A13: Workpaper tab: items with exception (current copy) | B13: =Workpaper!B67 -> 1 | C13: INFO | D13: See Workpaper!B69 for the suggested result.
